Workbook
Name Slicer_Department_Name: #N/A
Name Slicer_Emp_ID: #N/A
Name Slicer_Employment_Status3: #N/A
Name Slicer_Performance_Band: #N/A

Sheet Raw_Employee_Data
A1: Emp ID | B1: First_Name | C1: Last_Name | D1: Dept Code | E1: Hire Date | F1: Salary | G1: Performance Score | H1: Employment Status
A2: EMP127 | B2: Emily | C2: Brown | D2: IT02 | E2: 43093 | F2: 50361 | G2: 52 | H2: active
A3: EMP046 | B3: Richard | C3: Hernandez | D3: MKT04 | E3: 44659 | F3: 112673 | G3: 70 | H3: ACTIVE
A4: EMP134 | B4: Emily | C4: Gonzalez | D4: IT02 | E4: 42431 | F4: 114425 | G4: 54 | H4: LEFT
A5: EMP139 | B5: John | C5: Martinez | D5: FIN03 | E5: 45110 | F5: 103831 | G5: 70 | H5: active
A6: EMP112 | B6: Thomas | C6: Smith | D6: IT02 | E6: 44977 | F6: 73785 | G6: 40 | H6: Left
A7: EMP030 | B7: Emily | C7: Johnson | D7: OPS06 | E7: 02-Mar-20 | F7: 115882 | G7: 49 | H7: ACTIVE
A8: EMP096 | B8: John | C8: Wilson | D8: OPS06 | E8: 45272 | F8: 59980 | G8: 70 | H8: Left
A9: EMP098 | B9: Jessica | C9: Smith | D9: OPS06 | E9: 44174 | F9: 68728 | G9: 45 | H9: ACTIVE
A10: EMP095 | C10: Rodriguez | D10: FIN03 | E10: 43107 | F10: 102139 | G10: 79 | H10: active
A11: EMP140 | B11: Michael | C11: Martinez | D11: SAL05 | E11: 42676 | F11: 94998 | G11: 58 | H11: Active
A12: EMP020 | B12: Emily | C12: Miller | D12: sal05 | E12: 43911 | F12: 118635 | G12: 49 | H12: Active
A13: EMP057 | B13: Emily | C13: Hernandez | D13: IT02 | E13: 42425 | F13: 76918 | G13: 62 | H13: Actv
A14: EMP016 | B14: Jane | C14: Williams | D14: mkt04 | E14: 17-Jun-21 | F14: 61408 | G14: 48 | H14: ACTIVE
A15: EMP070 | B15: Jane | C15: Miller | D15: MKT04 | E15: 44001 | F15: 99990 | G15: 54 | H15: Actv
A16: EMP025 | B16: Robert | C16: Jones | D16: MKT04 | E16: 43820 | F16: 80385 | G16: 70 | H16: active
A17: EMP031 | B17: Thomas | C17: Rodriguez | D17: SAL05 | E17: 45169 | F17: 65290 | G17: 77 | H17: active
A18: EMP126 | B18: Emily | C18: Davis | D18: IT02 | E18: 42337 | F18: 105765 | G18: 42 | H18: Active
A19: EMP109 | B19: James | C19: Martinez | D19: SAL05 | E19: 42899 | F19: 102921 | G19: 49 | H19: ACTIVE
A20: EMP066 | B20: Ashley | C20: Lopez | D20: MKT04 | E20: 43235 | F20: 73984 | G20: 93 | H20: Actv
A21: EMP120 | B21: Amanda | C21: Gonzalez | D21: IT02 | E21: 42575 | F21: 83604 | G21: 75 | H21: Actv
A22: EMP019 | B22: Michael | C22: Hernandez | D22: FIN03 | E22: 43076 | F22: 118527 | G22: 50 | H22: Actv
A23: EMP013 | B23: Richard | C23: Hernandez | D23: MKT04 | E23: 44353 | F23: 107871 | G23: 88 | H23: active
A24: EMP010 | B24: Michael | C24: Rodriguez | D24: IT02 | E24: 44815 | F24: 93956 | G24: 50 | H24: LEFT
A25: EMP032 | B25: Jessica | C25: Johnson | D25: FIN03 | E25: 42565 | F25: 100851 | G25: 64 | H25: ACTIVE
A26: EMP082 | B26: Ashley | C26: Williams | D26: SAL05 | E26: 44728 | F26: 68655 | G26: 32 | H26: active
A27: EMP052 | C27: Williams | D27: SAL05 | E27: 45134 | F27: 81205 | G27: 59 | H27: Actv
A28: EMP129 | B28: John | C28: Wilson | D28: SAL05 | E28: 09/24/2019 | F28: 77610 | G28: 88 | H28: Actv
A29: EMP146 | B29: Thomas | C29: Rodriguez | D29: it02 | E29: 44765 | F29: 50873 | G29: 90 | H29: Active
A30: EMP099 | B30: Michael | C30: Wilson | D30: fin03 | E30: 13-May-18 | F30: 85312 | G30: 66 | H30: active
A31: EMP015 | B31: John | C31: Rodriguez | D31: SAL05 | E31: 42202 | F31: 83604 | G31: 68 | H31: active
A32: EMP076 | B32: Thomas | C32: Hernandez | D32: OPS06 | E32: 05-Aug-15 | F32: 97055 | G32: 80 | H32: Actv
A33: EMP137 | B33: Michael | C33: Johnson | D33: IT02 | E33: 45195 | F33: 66069 | G33: 72 | H33: Actv
A34: EMP056 | B34: Sarah | C34: Brown | D34: it02 | E34: 10-Jun-19 | F34: 90157 | G34: 58 | H34: active
A35: EMP125 | B35: Jane | C35: Martinez | D35: HR01 | E35: 44578 | F35: 59899 | G35: 78 | H35: Actv
A36: EMP085 | B36: Emily | C36: Jones | D36: FIN03 | E36: 03-Jul-17 | F36: 113389 | G36: 30 | H36: ACTIVE
A37: EMP106 | C37: Brown | D37: IT02 | E37: 01-Sep-15 | F37: 102691 | G37: 52 | H37: Active
A38: EMP043 | B38: John | C38: Wilson | D38: OPS06 | E38: 03-Aug-22 | F38: 111845 | G38: 98 | H38: active
A39: EMP068 | B39: Melissa | C39: Brown | D39: SAL05 | E39: 06/29/2022 | F39: 69219 | G39: 93 | H39: Actv
A40: EMP128 | B40: Michael | C40: Smith | D40: FIN03 | E40: 43949 | F40: 83604 | G40: 80 | H40: left
...

Sheet Lookup_Departments
A1: Dept_Code | B1: Department_Name
A2: HR01 | B2: Human Resources
A3: IT02 | B3: Information Technology
A4: FIN03 | B4: Finance
A5: MKT04 | B5: Marketing
A6: SAL05 | B6: Sales
A7: OPS06 | B7: Operations

Sheet Lookup_Performance
A1: Min_Score | B1: Max_Score | C1: Performance_Band | D1: Bonus_Percentage
A2: 0 | B2: 49 | C2: Needs Improvement | D2: 0
A3: 50 | B3: 69 | C3: Developing | D3: 0.02
A4: 70 | B4: 84 | C4: Achieving | D4: 0.05
A5: 85 | B5: 94 | C5: Exceeding | D5: 0.08
A6: 95 | B6: 100 | C6: Outstanding | D6: 0.12

Sheet Cleaned Data
A1: Emp ID | B1: First_Name | C1: Last_Name | D1: Full Name | E1: Department Name | F1: Department Code | G1: Dept Code | H1: Hire Date | I1: Year of Service | J1: Hire Date2 | K1: Salary | L1: Performance Score | M1: Employment Status | N1: Employment _Status | O1: Performance Band | P1: Bonus Percentage | Q1: Eligible Bonus Amount
A2: EMP127 | B2: Emily | C2: Brown | D2: =IF(AND(ISBLANK(B2), ISBLANK(C2)), "- -", IF(ISBLANK(B2), "- " & TRIM(PROPER(C2)), IF(ISBLANK(C2), TRIM(PROPER(B2)) & " -", _xlfn.TEXTJOIN(" ", TRUE, TRIM(PROPER(B2)), TRIM(PROPER(C2)))))) -> Emily Brown | E2: =_xlfn.XLOOKUP(F2, Lookup_Departments!$A$2:$A$7, Lookup_Departments!$B$2:$B$7, "Unknown") -> Information Technology | F2: =UPPER(TRIM(G2)) -> IT02 | G2: IT02 | H2: =DATEVALUE(TEXT(J2, "dd-mmm-yyyy")) -> 43093 | I2: =DATEDIF(H2, TODAY(), "Y") -> 8 | J2: 43093 | K2: 50361 | L2: 52 | M2: active | N2: {=_xlfn.SWITCH(TRIM(PROPER(M2)), "Active", "Active", "Actv", "Active", "Left", "Left", "Resigned", "Left", "Unknown")} -> Active | O2: =_xlfn.XLOOKUP(L2, Lookup_Performance!$A$2:$A$6, Lookup_Performance!$C$2:$C$6, "No Score", -1) -> Developing | P2: =_xlfn.XLOOKUP(L2, Lookup_Performance!$A$2:$A$6, Lookup_Performance!$D$2:$D$6, 0, -1) -> 0.02 | Q2: =K2*P2 -> 1007.22
A3: EMP046 | B3: Richard | C3: Hernandez | D3: =IF(AND(ISBLANK(B3), ISBLANK(C3)), "- -", IF(ISBLANK(B3), "- " & TRIM(PROPER(C3)), IF(ISBLANK(C3), TRIM(PROPER(B3)) & " -", _xlfn.TEXTJOIN(" ", TRUE, TRIM(PROPER(B3)), TRIM(PROPER(C3)))))) -> Richard Hernandez | E3: =_xlfn.XLOOKUP(F3, Lookup_Departments!$A$2:$A$7, Lookup_Departments!$B$2:$B$7, "Unknown") -> Marketing | F3: =UPPER(TRIM(G3)) -> MKT04 | G3: MKT04 | H3: =DATEVALUE(TEXT(J3, "dd-mmm-yyyy")) -> 44659 | I3: =DATEDIF(H3, TODAY(), "Y") -> 4 | J3: 44659 | K3: 112673 | L3: 70 | M3: ACTIVE | N3: {=_xlfn.SWITCH(TRIM(PROPER(M3)), "Active", "Active", "Actv", "Active", "Left", "Left", "Resigned", "Left", "Unknown")} -> Active | O3: =_xlfn.XLOOKUP(L3, Lookup_Performance!$A$2:$A$6, Lookup_Performance!$C$2:$C$6, "No Score", -1) -> Achieving | P3: =_xlfn.XLOOKUP(L3, Lookup_Performance!$A$2:$A$6, Lookup_Performance!$D$2:$D$6, 0, -1) -> 0.05 | Q3: =K3*P3 -> 5633.65
A4: EMP134 | B4: Emily | C4: Gonzalez | D4: =IF(AND(ISBLANK(B4), ISBLANK(C4)), "- -", IF(ISBLANK(B4), "- " & TRIM(PROPER(C4)), IF(ISBLANK(C4), TRIM(PROPER(B4)) & " -", _xlfn.TEXTJOIN(" ", TRUE, TRIM(PROPER(B4)), TRIM(PROPER(C4)))))) -> Emily Gonzalez | E4: =_xlfn.XLOOKUP(F4, Lookup_Departments!$A$2:$A$7, Lookup_Departments!$B$2:$B$7, "Unknown") -> Information Technology | F4: =UPPER(TRIM(G4)) -> IT02 | G4: IT02 | H4: =DATEVALUE(TEXT(J4, "dd-mmm-yyyy")) -> 42431 | I4: =DATEDIF(H4, TODAY(), "Y") -> 10 | J4: 42431 | K4: 114425 | L4: 54 | M4: LEFT | N4: {=_xlfn.SWITCH(TRIM(PROPER(M4)), "Active", "Active", "Actv", "Active", "Left", "Left", "Resigned", "Left", "Unknown")} -> Left | O4: =_xlfn.XLOOKUP(L4, Lookup_Performance!$A$2:$A$6, Lookup_Performance!$C$2:$C$6, "No Score", -1) -> Developing | P4: =_xlfn.XLOOKUP(L4, Lookup_Performance!$A$2:$A$6, Lookup_Performance!$D$2:$D$6, 0, -1) -> 0.02 | Q4: =K4*P4 -> 2288.5
A5: EMP139 | B5: John | C5: Martinez | D5: =IF(AND(ISBLANK(B5), ISBLANK(C5)), "- -", IF(ISBLANK(B5), "- " & TRIM(PROPER(C5)), IF(ISBLANK(C5), TRIM(PROPER(B5)) & " -", _xlfn.TEXTJOIN(" ", TRUE, TRIM(PROPER(B5)), TRIM(PROPER(C5)))))) -> John Martinez | E5: =_xlfn.XLOOKUP(F5, Lookup_Departments!$A$2:$A$7, Lookup_Departments!$B$2:$B$7, "Unknown") -> Finance | F5: =UPPER(TRIM(G5)) -> FIN03 | G5: FIN03 | H5: =DATEVALUE(TEXT(J5, "dd-mmm-yyyy")) -> 45110 | I5: =DATEDIF(H5, TODAY(), "Y") -> 3 | J5: 45110 | K5: 103831 | L5: 70 | M5: active | N5: {=_xlfn.SWITCH(TRIM(PROPER(M5)), "Active", "Active", "Actv", "Active", "Left", "Left", "Resigned", "Left", "Unknown")} -> Active | O5: =_xlfn.XLOOKUP(L5, Lookup_Performance!$A$2:$A$6, Lookup_Performance!$C$2:$C$6, "No Score", -1) -> Achieving | P5: =_xlfn.XLOOKUP(L5, Lookup_Performance!$A$2:$A$6, Lookup_Performance!$D$2:$D$6, 0, -1) -> 0.05 | Q5: =K5*P5 -> 5191.55
A6: EMP112 | B6: Thomas | C6: Smith | D6: =IF(AND(ISBLANK(B6), ISBLANK(C6)), "- -", IF(ISBLANK(B6), "- " & TRIM(PROPER(C6)), IF(ISBLANK(C6), TRIM(PROPER(B6)) & " -", _xlfn.TEXTJOIN(" ", TRUE, TRIM(PROPER(B6)), TRIM(PROPER(C6)))))) -> Thomas Smith | E6: =_xlfn.XLOOKUP(F6, Lookup_Departments!$A$2:$A$7, Lookup_Departments!$B$2:$B$7, "Unknown") -> Information Technology | F6: =UPPER(TRIM(G6)) -> IT02 | G6: IT02 | H6: =DATEVALUE(TEXT(J6, "dd-mmm-yyyy")) -> 44977 | I6: =DATEDIF(H6, TODAY(), "Y") -> 3 | J6: 44977 | K6: 73785 | L6: 40 | M6: Left | N6: {=_xlfn.SWITCH(TRIM(PROPER(M6)), "Active", "Active", "Actv", "Active", "Left", "Left", "Resigned", "Left", "Unknown")} -> Left | O6: =_xlfn.XLOOKUP(L6, Lookup_Performance!$A$2:$A$6, Lookup_Performance!$C$2:$C$6, "No Score", -1) -> Needs Improvement | P6: =_xlfn.XLOOKUP(L6, Lookup_Performance!$A$2:$A$6, Lookup_Performance!$D$2:$D$6, 0, -1) -> 0 | Q6: =K6*P6 -> 0
A7: EMP030 | B7: Emily | C7: Johnson | D7: =IF(AND(ISBLANK(B7), ISBLANK(C7)), "- -", IF(ISBLANK(B7), "- " & TRIM(PROPER(C7)), IF(ISBLANK(C7), TRIM(PROPER(B7)) & " -", _xlfn.TEXTJOIN(" ", TRUE, TRIM(PROPER(B7)), TRIM(PROPER(C7)))))) -> Emily Johnson | E7: =_xlfn.XLOOKUP(F7, Lookup_Departments!$A$2:$A$7, Lookup_Departments!$B$2:$B$7, "Unknown") -> Operations | F7: =UPPER(TRIM(G7)) -> OPS06 | G7: OPS06 | H7: =DATEVALUE(TEXT(J7, "dd-mmm-yyyy")) -> 43892 | I7: =DATEDIF(H7, TODAY(), "Y") -> 6 | J7: 02-Mar-20 | K7: 115882 | L7: 49 | M7: ACTIVE | N7: {=_xlfn.SWITCH(TRIM(PROPER(M7)), "Active", "Active", "Actv", "Active", "Left", "Left", "Resigned", "Left", "Unknown")} -> Active | O7: =_xlfn.XLOOKUP(L7, Lookup_Performance!$A$2:$A$6, Lookup_Performance!$C$2:$C$6, "No Score", -1) -> Needs Improvement | P7: =_xlfn.XLOOKUP(L7, Lookup_Performance!$A$2:$A$6, Lookup_Performance!$D$2:$D$6, 0, -1) -> 0 | Q7: =K7*P7 -> 0
A8: EMP096 | B8: John | C8: Wilson | D8: =IF(AND(ISBLANK(B8), ISBLANK(C8)), "- -", IF(ISBLANK(B8), "- " & TRIM(PROPER(C8)), IF(ISBLANK(C8), TRIM(PROPER(B8)) & " -", _xlfn.TEXTJOIN(" ", TRUE, TRIM(PROPER(B8)), TRIM(PROPER(C8)))))) -> John Wilson | E8: =_xlfn.XLOOKUP(F8, Lookup_Departments!$A$2:$A$7, Lookup_Departments!$B$2:$B$7, "Unknown") -> Operations | F8: =UPPER(TRIM(G8)) -> OPS06 | G8: OPS06 | H8: =DATEVALUE(TEXT(J8, "dd-mmm-yyyy")) -> 45272 | I8: =DATEDIF(H8, TODAY(), "Y") -> 2 | J8: 45272 | K8: 59980 | L8: 70 | M8: Left | N8: {=_xlfn.SWITCH(TRIM(PROPER(M8)), "Active", "Active", "Actv", "Active", "Left", "Left", "Resigned", "Left", "Unknown")} -> Left | O8: =_xlfn.XLOOKUP(L8, Lookup_Performance!$A$2:$A$6, Lookup_Performance!$C$2:$C$6, "No Score", -1) -> Achieving | P8: =_xlfn.XLOOKUP(L8, Lookup_Performance!$A$2:$A$6, Lookup_Performance!$D$2:$D$6, 0, -1) -> 0.05 | Q8: =K8*P8 -> 2999
A9: EMP098 | B9: Jessica | C9: Smith | D9: =IF(AND(ISBLANK(B9), ISBLANK(C9)), "- -", IF(ISBLANK(B9), "- " & TRIM(PROPER(C9)), IF(ISBLANK(C9), TRIM(PROPER(B9)) & " -", _xlfn.TEXTJOIN(" ", TRUE, TRIM(PROPER(B9)), TRIM(PROPER(C9)))))) -> Jessica Smith | E9: =_xlfn.XLOOKUP(F9, Lookup_Departments!$A$2:$A$7, Lookup_Departments!$B$2:$B$7, "Unknown") -> Operations | F9: =UPPER(TRIM(G9)) -> OPS06 | G9: OPS06 | H9: =DATEVALUE(TEXT(J9, "dd-mmm-yyyy")) -> 44174 | I9: =DATEDIF(H9, TODAY(), "Y") -> 5 | J9: 44174 | K9: 68728 | L9: 45 | M9: ACTIVE | N9: {=_xlfn.SWITCH(TRIM(PROPER(M9)), "Active", "Active", "Actv", "Active", "Left", "Left", "Resigned", "Left", "Unknown")} -> Active | O9: =_xlfn.XLOOKUP(L9, Lookup_Performance!$A$2:$A$6, Lookup_Performance!$C$2:$C$6, "No Score", -1) -> Needs Improvement | P9: =_xlfn.XLOOKUP(L9, Lookup_Performance!$A$2:$A$6, Lookup_Performance!$D$2:$D$6, 0, -1) -> 0 | Q9: =K9*P9 -> 0
A10: EMP095 | C10: Rodriguez | D10: =IF(AND(ISBLANK(B10), ISBLANK(C10)), "- -", IF(ISBLANK(B10), "- " & TRIM(PROPER(C10)), IF(ISBLANK(C10), TRIM(PROPER(B10)) & " -", _xlfn.TEXTJOIN(" ", TRUE, TRIM(PROPER(B10)), TRIM(PROPER(C10)))))) -> - Rodriguez | E10: =_xlfn.XLOOKUP(F10, Lookup_Departments!$A$2:$A$7, Lookup_Departments!$B$2:$B$7, "Unknown") -> Finance | F10: =UPPER(TRIM(G10)) -> FIN03 | G10: FIN03 | H10: =DATEVALUE(TEXT(J10, "dd-mmm-yyyy")) -> 43107 | I10: =DATEDIF(H10, TODAY(), "Y") -> 8 | J10: 43107 | K10: 102139 | L10: 79 | M10: active | N10: {=_xlfn.SWITCH(TRIM(PROPER(M10)), "Active", "Active", "Actv", "Active", "Left", "Left", "Resigned", "Left", "Unknown")} -> Active | O10: =_xlfn.XLOOKUP(L10, Lookup_Performance!$A$2:$A$6, Lookup_Performance!$C$2:$C$6, "No Score", -1) -> Achieving | P10: =_xlfn.XLOOKUP(L10, Lookup_Performance!$A$2:$A$6, Lookup_Performance!$D$2:$D$6, 0, -1) -> 0.05 | Q10: =K10*P10 -> 5106.95
A11: EMP140 | B11: Michael | C11: Martinez | D11: =IF(AND(ISBLANK(B11), ISBLANK(C11)), "- -", IF(ISBLANK(B11), "- " & TRIM(PROPER(C11)), IF(ISBLANK(C11), TRIM(PROPER(B11)) & " -", _xlfn.TEXTJOIN(" ", TRUE, TRIM(PROPER(B11)), TRIM(PROPER(C11)))))) -> Michael Martinez | E11: =_xlfn.XLOOKUP(F11, Lookup_Departments!$A$2:$A$7, Lookup_Departments!$B$2:$B$7, "Unknown") -> Sales | F11: =UPPER(TRIM(G11)) -> SAL05 | G11: SAL05 | H11: =DATEVALUE(TEXT(J11, "dd-mmm-yyyy")) -> 42676 | I11: =DATEDIF(H11, TODAY(), "Y") -> 9 | J11: 42676 | K11: 94998 | L11: 58 | M11: Active | N11: {=_xlfn.SWITCH(TRIM(PROPER(M11)), "Active", "Active", "Actv", "Active", "Left", "Left", "Resigned", "Left", "Unknown")} -> Active | O11: =_xlfn.XLOOKUP(L11, Lookup_Performance!$A$2:$A$6, Lookup_Performance!$C$2:$C$6, "No Score", -1) -> Developing | P11: =_xlfn.XLOOKUP(L11, Lookup_Performance!$A$2:$A$6, Lookup_Performance!$D$2:$D$6, 0, -1) -> 0.02 | Q11: =K11*P11 -> 1899.96
A12: EMP020 | B12: Emily | C12: Miller | D12: =IF(AND(ISBLANK(B12), ISBLANK(C12)), "- -", IF(ISBLANK(B12), "- " & TRIM(PROPER(C12)), IF(ISBLANK(C12), TRIM(PROPER(B12)) & " -", _xlfn.TEXTJOIN(" ", TRUE, TRIM(PROPER(B12)), TRIM(PROPER(C12)))))) -> Emily Miller | E12: =_xlfn.XLOOKUP(F12, Lookup_Departments!$A$2:$A$7, Lookup_Departments!$B$2:$B$7, "Unknown") -> Sales | F12: =UPPER(TRIM(G12)) -> SAL05 | G12: sal05 | H12: =DATEVALUE(TEXT(J12, "dd-mmm-yyyy")) -> 43911 | I12: =DATEDIF(H12, TODAY(), "Y") -> 6 | J12: 43911 | K12: 118635 | L12: 49 | M12: Active | N12: {=_xlfn.SWITCH(TRIM(PROPER(M12)), "Active", "Active", "Actv", "Active", "Left", "Left", "Resigned", "Left", "Unknown")} -> Active | O12: =_xlfn.XLOOKUP(L12, Lookup_Performance!$A$2:$A$6, Lookup_Performance!$C$2:$C$6, "No Score", -1) -> Needs Improvement | P12: =_xlfn.XLOOKUP(L12, Lookup_Performance!$A$2:$A$6, Lookup_Performance!$D$2:$D$6, 0, -1) -> 0 | Q12: =K12*P12 -> 0
A13: EMP057 | B13: Emily | C13: Hernandez | D13: =IF(AND(ISBLANK(B13), ISBLANK(C13)), "- -", IF(ISBLANK(B13), "- " & TRIM(PROPER(C13)), IF(ISBLANK(C13), TRIM(PROPER(B13)) & " -", _xlfn.TEXTJOIN(" ", TRUE, TRIM(PROPER(B13)), TRIM(PROPER(C13)))))) -> Emily Hernandez | E13: =_xlfn.XLOOKUP(F13, Lookup_Departments!$A$2:$A$7, Lookup_Departments!$B$2:$B$7, "Unknown") -> Information Technology | F13: =UPPER(TRIM(G13)) -> IT02 | G13: IT02 | H13: =DATEVALUE(TEXT(J13, "dd-mmm-yyyy")) -> 42425 | I13: =DATEDIF(H13, TODAY(), "Y") -> 10 | J13: 42425 | K13: 76918 | L13: 62 | M13: Actv | N13: {=_xlfn.SWITCH(TRIM(PROPER(M13)), "Active", "Active", "Actv", "Active", "Left", "Left", "Resigned", "Left", "Unknown")} -> Active | O13: =_xlfn.XLOOKUP(L13, Lookup_Performance!$A$2:$A$6, Lookup_Performance!$C$2:$C$6, "No Score", -1) -> Developing | P13: =_xlfn.XLOOKUP(L13, Lookup_Performance!$A$2:$A$6, Lookup_Performance!$D$2:$D$6, 0, -1) -> 0.02 | Q13: =K13*P13 -> 1538.36
A14: EMP016 | B14: Jane | C14: Williams | D14: =IF(AND(ISBLANK(B14), ISBLANK(C14)), "- -", IF(ISBLANK(B14), "- " & TRIM(PROPER(C14)), IF(ISBLANK(C14), TRIM(PROPER(B14)) & " -", _xlfn.TEXTJOIN(" ", TRUE, TRIM(PROPER(B14)), TRIM(PROPER(C14)))))) -> Jane Williams | E14: =_xlfn.XLOOKUP(F14, Lookup_Departments!$A$2:$A$7, Lookup_Departments!$B$2:$B$7, "Unknown") -> Marketing | F14: =UPPER(TRIM(G14)) -> MKT04 | G14: mkt04 | H14: =DATEVALUE(TEXT(J14, "dd-mmm-yyyy")) -> 44364 | I14: =DATEDIF(H14, TODAY(), "Y") -> 5 | J14: 17-Jun-21 | K14: 61408 | L14: 48 | M14: ACTIVE | N14: {=_xlfn.SWITCH(TRIM(PROPER(M14)), "Active", "Active", "Actv", "Active", "Left", "Left", "Resigned", "Left", "Unknown")} -> Active | O14: =_xlfn.XLOOKUP(L14, Lookup_Performance!$A$2:$A$6, Lookup_Performance!$C$2:$C$6, "No Score", -1) -> Needs Improvement | P14: =_xlfn.XLOOKUP(L14, Lookup_Performance!$A$2:$A$6, Lookup_Performance!$D$2:$D$6, 0, -1) -> 0 | Q14: =K14*P14 -> 0
A15: EMP070 | B15: Jane | C15: Miller | D15: =IF(AND(ISBLANK(B15), ISBLANK(C15)), "- -", IF(ISBLANK(B15), "- " & TRIM(PROPER(C15)), IF(ISBLANK(C15), TRIM(PROPER(B15)) & " -", _xlfn.TEXTJOIN(" ", TRUE, TRIM(PROPER(B15)), TRIM(PROPER(C15)))))) -> Jane Miller | E15: =_xlfn.XLOOKUP(F15, Lookup_Departments!$A$2:$A$7, Lookup_Departments!$B$2:$B$7, "Unknown") -> Marketing | F15: =UPPER(TRIM(G15)) -> MKT04 | G15: MKT04 | H15: =DATEVALUE(TEXT(J15, "dd-mmm-yyyy")) -> 44001 | I15: =DATEDIF(H15, TODAY(), "Y") -> 6 | J15: 44001 | K15: 99990 | L15: 54 | M15: Actv | N15: {=_xlfn.SWITCH(TRIM(PROPER(M15)), "Active", "Active", "Actv", "Active", "Left", "Left", "Resigned", "Left", "Unknown")} -> Active | O15: =_xlfn.XLOOKUP(L15, Lookup_Performance!$A$2:$A$6, Lookup_Performance!$C$2:$C$6, "No Score", -1) -> Developing | P15: =_xlfn.XLOOKUP(L15, Lookup_Performance!$A$2:$A$6, Lookup_Performance!$D$2:$D$6, 0, -1) -> 0.02 | Q15: =K15*P15 -> 1999.8
A16: EMP025 | B16: Robert | C16: Jones | D16: =IF(AND(ISBLANK(B16), ISBLANK(C16)), "- -", IF(ISBLANK(B16), "- " & TRIM(PROPER(C16)), IF(ISBLANK(C16), TRIM(PROPER(B16)) & " -", _xlfn.TEXTJOIN(" ", TRUE, TRIM(PROPER(B16)), TRIM(PROPER(C16)))))) -> Robert Jones | E16: =_xlfn.XLOOKUP(F16, Lookup_Departments!$A$2:$A$7, Lookup_Departments!$B$2:$B$7, "Unknown") -> Marketing | F16: =UPPER(TRIM(G16)) -> MKT04 | G16: MKT04 | H16: =DATEVALUE(TEXT(J16, "dd-mmm-yyyy")) -> 43820 | I16: =DATEDIF(H16, TODAY(), "Y") -> 6 | J16: 43820 | K16: 80385 | L16: 70 | M16: active | N16: {=_xlfn.SWITCH(TRIM(PROPER(M16)), "Active", "Active", "Actv", "Active", "Left", "Left", "Resigned", "Left", "Unknown")} -> Active | O16: =_xlfn.XLOOKUP(L16, Lookup_Performance!$A$2:$A$6, Lookup_Performance!$C$2:$C$6, "No Score", -1) -> Achieving | P16: =_xlfn.XLOOKUP(L16, Lookup_Performance!$A$2:$A$6, Lookup_Performance!$D$2:$D$6, 0, -1) -> 0.05 | Q16: =K16*P16 -> 4019.25
A17: EMP031 | B17: Thomas | C17: Rodriguez | D17: =IF(AND(ISBLANK(B17), ISBLANK(C17)), "- -", IF(ISBLANK(B17), "- " & TRIM(PROPER(C17)), IF(ISBLANK(C17), TRIM(PROPER(B17)) & " -", _xlfn.TEXTJOIN(" ", TRUE, TRIM(PROPER(B17)), TRIM(PROPER(C17)))))) -> Thomas Rodriguez | E17: =_xlfn.XLOOKUP(F17, Lookup_Departments!$A$2:$A$7, Lookup_Departments!$B$2:$B$7, "Unknown") -> Sales | F17: =UPPER(TRIM(G17)) -> SAL05 | G17: SAL05 | H17: =DATEVALUE(TEXT(J17, "dd-mmm-yyyy")) -> 45169 | I17: =DATEDIF(H17, TODAY(), "Y") -> 2 | J17: 45169 | K17: 65290 | L17: 77 | M17: active | N17: {=_xlfn.SWITCH(TRIM(PROPER(M17)), "Active", "Active", "Actv", "Active", "Left", "Left", "Resigned", "Left", "Unknown")} -> Active | O17: =_xlfn.XLOOKUP(L17, Lookup_Performance!$A$2:$A$6, Lookup_Performance!$C$2:$C$6, "No Score", -1) -> Achieving | P17: =_xlfn.XLOOKUP(L17, Lookup_Performance!$A$2:$A$6, Lookup_Performance!$D$2:$D$6, 0, -1) -> 0.05 | Q17: =K17*P17 -> 3264.5
A18: EMP126 | B18: Emily | C18: Davis | D18: =IF(AND(ISBLANK(B18), ISBLANK(C18)), "- -", IF(ISBLANK(B18), "- " & TRIM(PROPER(C18)), IF(ISBLANK(C18), TRIM(PROPER(B18)) & " -", _xlfn.TEXTJOIN(" ", TRUE, TRIM(PROPER(B18)), TRIM(PROPER(C18)))))) -> Emily Davis | E18: =_xlfn.XLOOKUP(F18, Lookup_Departments!$A$2:$A$7, Lookup_Departments!$B$2:$B$7, "Unknown") -> Information Technology | F18: =UPPER(TRIM(G18)) -> IT02 | G18: IT02 | H18: =DATEVALUE(TEXT(J18, "dd-mmm-yyyy")) -> 42337 | I18: =DATEDIF(H18, TODAY(), "Y") -> 10 | J18: 42337 | K18: 105765 | L18: 42 | M18: Active | N18: {=_xlfn.SWITCH(TRIM(PROPER(M18)), "Active", "Active", "Actv", "Active", "Left", "Left", "Resigned", "Left", "Unknown")} -> Active | O18: =_xlfn.XLOOKUP(L18, Lookup_Performance!$A$2:$A$6, Lookup_Performance!$C$2:$C$6, "No Score", -1) -> Needs Improvement | P18: =_xlfn.XLOOKUP(L18, Lookup_Performance!$A$2:$A$6, Lookup_Performance!$D$2:$D$6, 0, -1) -> 0 | Q18: =K18*P18 -> 0
A19: EMP109 | B19: James | C19: Martinez | D19: =IF(AND(ISBLANK(B19), ISBLANK(C19)), "- -", IF(ISBLANK(B19), "- " & TRIM(PROPER(C19)), IF(ISBLANK(C19), TRIM(PROPER(B19)) & " -", _xlfn.TEXTJOIN(" ", TRUE, TRIM(PROPER(B19)), TRIM(PROPER(C19)))))) -> James Martinez | E19: =_xlfn.XLOOKUP(F19, Lookup_Departments!$A$2:$A$7, Lookup_Departments!$B$2:$B$7, "Unknown") -> Sales | F19: =UPPER(TRIM(G19)) -> SAL05 | G19: SAL05 | H19: =DATEVALUE(TEXT(J19, "dd-mmm-yyyy")) -> 42899 | I19: =DATEDIF(H19, TODAY(), "Y") -> 9 | J19: 42899 | K19: 102921 | L19: 49 | M19: ACTIVE | N19: {=_xlfn.SWITCH(TRIM(PROPER(M19)), "Active", "Active", "Actv", "Active", "Left", "Left", "Resigned", "Left", "Unknown")} -> Active | O19: =_xlfn.XLOOKUP(L19, Lookup_Performance!$A$2:$A$6, Lookup_Performance!$C$2:$C$6, "No Score", -1) -> Needs Improvement | P19: =_xlfn.XLOOKUP(L19, Lookup_Performance!$A$2:$A$6, Lookup_Performance!$D$2:$D$6, 0, -1) -> 0 | Q19: =K19*P19 -> 0
A20: EMP066 | B20: Ashley | C20: Lopez | D20: =IF(AND(ISBLANK(B20), ISBLANK(C20)), "- -", IF(ISBLANK(B20), "- " & TRIM(PROPER(C20)), IF(ISBLANK(C20), TRIM(PROPER(B20)) & " -", _xlfn.TEXTJOIN(" ", TRUE, TRIM(PROPER(B20)), TRIM(PROPER(C20)))))) -> Ashley Lopez | E20: =_xlfn.XLOOKUP(F20, Lookup_Departments!$A$2:$A$7, Lookup_Departments!$B$2:$B$7, "Unknown") -> Marketing | F20: =UPPER(TRIM(G20)) -> MKT04 | G20: MKT04 | H20: =DATEVALUE(TEXT(J20, "dd-mmm-yyyy")) -> 43235 | I20: =DATEDIF(H20, TODAY(), "Y") -> 8 | J20: 43235 | K20: 73984 | L20: 93 | M20: Actv | N20: {=_xlfn.SWITCH(TRIM(PROPER(M20)), "Active", "Active", "Actv", "Active", "Left", "Left", "Resigned", "Left", "Unknown")} -> Active | O20: =_xlfn.XLOOKUP(L20, Lookup_Performance!$A$2:$A$6, Lookup_Performance!$C$2:$C$6, "No Score", -1) -> Exceeding | P20: =_xlfn.XLOOKUP(L20, Lookup_Performance!$A$2:$A$6, Lookup_Performance!$D$2:$D$6, 0, -1) -> 0.08 | Q20: =K20*P20 -> 5918.72
A21: EMP120 | B21: Amanda | C21: Gonzalez | D21: =IF(AND(ISBLANK(B21), ISBLANK(C21)), "- -", IF(ISBLANK(B21), "- " & TRIM(PROPER(C21)), IF(ISBLANK(C21), TRIM(PROPER(B21)) & " -", _xlfn.TEXTJOIN(" ", TRUE, TRIM(PROPER(B21)), TRIM(PROPER(C21)))))) -> Amanda Gonzalez | E21: =_xlfn.XLOOKUP(F21, Lookup_Departments!$A$2:$A$7, Lookup_Departments!$B$2:$B$7, "Unknown") -> Information Technology | F21: =UPPER(TRIM(G21)) -> IT02 | G21: IT02 | H21: =DATEVALUE(TEXT(J21, "dd-mmm-yyyy")) -> 42575 | I21: =DATEDIF(H21, TODAY(), "Y") -> 9 | J21: 42575 | K21: 83604 | L21: 75 | M21: Actv | N21: {=_xlfn.SWITCH(TRIM(PROPER(M21)), "Active", "Active", "Actv", "Active", "Left", "Left", "Resigned", "Left", "Unknown")} -> Active | O21: =_xlfn.XLOOKUP(L21, Lookup_Performance!$A$2:$A$6, Lookup_Performance!$C$2:$C$6, "No Score", -1) -> Achieving | P21: =_xlfn.XLOOKUP(L21, Lookup_Performance!$A$2:$A$6, Lookup_Performance!$D$2:$D$6, 0, -1) -> 0.05 | Q21: =K21*P21 -> 4180.2
A22: EMP019 | B22: Michael | C22: Hernandez | D22: =IF(AND(ISBLANK(B22), ISBLANK(C22)), "- -", IF(ISBLANK(B22), "- " & TRIM(PROPER(C22)), IF(ISBLANK(C22), TRIM(PROPER(B22)) & " -", _xlfn.TEXTJOIN(" ", TRUE, TRIM(PROPER(B22)), TRIM(PROPER(C22)))))) -> Michael Hernandez | E22: =_xlfn.XLOOKUP(F22, Lookup_Departments!$A$2:$A$7, Lookup_Departments!$B$2:$B$7, "Unknown") -> Finance | F22: =UPPER(TRIM(G22)) -> FIN03 | G22: FIN03 | H22: =DATEVALUE(TEXT(J22, "dd-mmm-yyyy")) -> 43076 | I22: =DATEDIF(H22, TODAY(), "Y") -> 8 | J22: 43076 | K22: 118527 | L22: 50 | M22: Actv | N22: {=_xlfn.SWITCH(TRIM(PROPER(M22)), "Active", "Active", "Actv", "Active", "Left", "Left", "Resigned", "Left", "Unknown")} -> Active | O22: =_xlfn.XLOOKUP(L22, Lookup_Performance!$A$2:$A$6, Lookup_Performance!$C$2:$C$6, "No Score", -1) -> Developing | P22: =_xlfn.XLOOKUP(L22, Lookup_Performance!$A$2:$A$6, Lookup_Performance!$D$2:$D$6, 0, -1) -> 0.02 | Q22: =K22*P22 -> 2370.54
A23: EMP013 | B23: Richard | C23: Hernandez | D23: =IF(AND(ISBLANK(B23), ISBLANK(C23)), "- -", IF(ISBLANK(B23), "- " & TRIM(PROPER(C23)), IF(ISBLANK(C23), TRIM(PROPER(B23)) & " -", _xlfn.TEXTJOIN(" ", TRUE, TRIM(PROPER(B23)), TRIM(PROPER(C23)))))) -> Richard Hernandez | E23: =_xlfn.XLOOKUP(F23, Lookup_Departments!$A$2:$A$7, Lookup_Departments!$B$2:$B$7, "Unknown") -> Marketing | F23: =UPPER(TRIM(G23)) -> MKT04 | G23: MKT04 | H23: =DATEVALUE(TEXT(J23, "dd-mmm-yyyy")) -> 44353 | I23: =DATEDIF(H23, TODAY(), "Y") -> 5 | J23: 44353 | K23: 107871 | L23: 88 | M23: active | N23: {=_xlfn.SWITCH(TRIM(PROPER(M23)), "Active", "Active", "Actv", "Active", "Left", "Left", "Resigned", "Left", "Unknown")} -> Active | O23: =_xlfn.XLOOKUP(L23, Lookup_Performance!$A$2:$A$6, Lookup_Performance!$C$2:$C$6, "No Score", -1) -> Exceeding | P23: =_xlfn.XLOOKUP(L23, Lookup_Performance!$A$2:$A$6, Lookup_Performance!$D$2:$D$6, 0, -1) -> 0.08 | Q23: =K23*P23 -> 8629.68
A24: EMP010 | B24: Michael | C24: Rodriguez | D24: =IF(AND(ISBLANK(B24), ISBLANK(C24)), "- -", IF(ISBLANK(B24), "- " & TRIM(PROPER(C24)), IF(ISBLANK(C24), TRIM(PROPER(B24)) & " -", _xlfn.TEXTJOIN(" ", TRUE, TRIM(PROPER(B24)), TRIM(PROPER(C24)))))) -> Michael Rodriguez | E24: =_xlfn.XLOOKUP(F24, Lookup_Departments!$A$2:$A$7, Lookup_Departments!$B$2:$B$7, "Unknown") -> Information Technology | F24: =UPPER(TRIM(G24)) -> IT02 | G24: IT02 | H24: =DATEVALUE(TEXT(J24, "dd-mmm-yyyy")) -> 44815 | I24: =DATEDIF(H24, TODAY(), "Y") -> 3 | J24: 44815 | K24: 93956 | L24: 50 | M24: LEFT | N24: {=_xlfn.SWITCH(TRIM(PROPER(M24)), "Active", "Active", "Actv", "Active", "Left", "Left", "Resigned", "Left", "Unknown")} -> Left | O24: =_xlfn.XLOOKUP(L24, Lookup_Performance!$A$2:$A$6, Lookup_Performance!$C$2:$C$6, "No Score", -1) -> Developing | P24: =_xlfn.XLOOKUP(L24, Lookup_Performance!$A$2:$A$6, Lookup_Performance!$D$2:$D$6, 0, -1) -> 0.02 | Q24: =K24*P24 -> 1879.12
A25: EMP032 | B25: Jessica | C25: Johnson | D25: =IF(AND(ISBLANK(B25), ISBLANK(C25)), "- -", IF(ISBLANK(B25), "- " & TRIM(PROPER(C25)), IF(ISBLANK(C25), TRIM(PROPER(B25)) & " -", _xlfn.TEXTJOIN(" ", TRUE, TRIM(PROPER(B25)), TRIM(PROPER(C25)))))) -> Jessica Johnson | E25: =_xlfn.XLOOKUP(F25, Lookup_Departments!$A$2:$A$7, Lookup_Departments!$B$2:$B$7, "Unknown") -> Finance | F25: =UPPER(TRIM(G25)) -> FIN03 | G25: FIN03 | H25: =DATEVALUE(TEXT(J25, "dd-mmm-yyyy")) -> 42565 | I25: =DATEDIF(H25, TODAY(), "Y") -> 9 | J25: 42565 | K25: 100851 | L25: 64 | M25: ACTIVE | N25: {=_xlfn.SWITCH(TRIM(PROPER(M25)), "Active", "Active", "Actv", "Active", "Left", "Left", "Resigned", "Left", "Unknown")} -> Active | O25: =_xlfn.XLOOKUP(L25, Lookup_Performance!$A$2:$A$6, Lookup_Performance!$C$2:$C$6, "No Score", -1) -> Developing | P25: =_xlfn.XLOOKUP(L25, Lookup_Performance!$A$2:$A$6, Lookup_Performance!$D$2:$D$6, 0, -1) -> 0.02 | Q25: =K25*P25 -> 2017.02
A26: EMP082 | B26: Ashley | C26: Williams | D26: =IF(AND(ISBLANK(B26), ISBLANK(C26)), "- -", IF(ISBLANK(B26), "- " & TRIM(PROPER(C26)), IF(ISBLANK(C26), TRIM(PROPER(B26)) & " -", _xlfn.TEXTJOIN(" ", TRUE, TRIM(PROPER(B26)), TRIM(PROPER(C26)))))) -> Ashley Williams | E26: =_xlfn.XLOOKUP(F26, Lookup_Departments!$A$2:$A$7, Lookup_Departments!$B$2:$B$7, "Unknown") -> Sales | F26: =UPPER(TRIM(G26)) -> SAL05 | G26: SAL05 | H26: =DATEVALUE(TEXT(J26, "dd-mmm-yyyy")) -> 44728 | I26: =DATEDIF(H26, TODAY(), "Y") -> 4 | J26: 44728 | K26: 68655 | L26: 32 | M26: active | N26: {=_xlfn.SWITCH(TRIM(PROPER(M26)), "Active", "Active", "Actv", "Active", "Left", "Left", "Resigned", "Left", "Unknown")} -> Active | O26: =_xlfn.XLOOKUP(L26, Lookup_Performance!$A$2:$A$6, Lookup_Performance!$C$2:$C$6, "No Score", -1) -> Needs Improvement | P26: =_xlfn.XLOOKUP(L26, Lookup_Performance!$A$2:$A$6, Lookup_Performance!$D$2:$D$6, 0, -1) -> 0 | Q26: =K26*P26 -> 0
A27: EMP052 | C27: Williams | D27: =IF(AND(ISBLANK(B27), ISBLANK(C27)), "- -", IF(ISBLANK(B27), "- " & TRIM(PROPER(C27)), IF(ISBLANK(C27), TRIM(PROPER(B27)) & " -", _xlfn.TEXTJOIN(" ", TRUE, TRIM(PROPER(B27)), TRIM(PROPER(C27)))))) -> - Williams | E27: =_xlfn.XLOOKUP(F27, Lookup_Departments!$A$2:$A$7, Lookup_Departments!$B$2:$B$7, "Unknown") -> Sales | F27: =UPPER(TRIM(G27)) -> SAL05 | G27: SAL05 | H27: =DATEVALUE(TEXT(J27, "dd-mmm-yyyy")) -> 45134 | I27: =DATEDIF(H27, TODAY(), "Y") -> 2 | J27: 45134 | K27: 81205 | L27: 59 | M27: Actv | N27: {=_xlfn.SWITCH(TRIM(PROPER(M27)), "Active", "Active", "Actv", "Active", "Left", "Left", "Resigned", "Left", "Unknown")} -> Active | O27: =_xlfn.XLOOKUP(L27, Lookup_Performance!$A$2:$A$6, Lookup_Performance!$C$2:$C$6, "No Score", -1) -> Developing | P27: =_xlfn.XLOOKUP(L27, Lookup_Performance!$A$2:$A$6, Lookup_Performance!$D$2:$D$6, 0, -1) -> 0.02 | Q27: =K27*P27 -> 1624.1
A28: EMP129 | B28: John | C28: Wilson | D28: =IF(AND(ISBLANK(B28), ISBLANK(C28)), "- -", IF(ISBLANK(B28), "- " & TRIM(PROPER(C28)), IF(ISBLANK(C28), TRIM(PROPER(B28)) & " -", _xlfn.TEXTJOIN(" ", TRUE, TRIM(PROPER(B28)), TRIM(PROPER(C28)))))) -> John Wilson | E28: =_xlfn.XLOOKUP(F28, Lookup_Departments!$A$2:$A$7, Lookup_Departments!$B$2:$B$7, "Unknown") -> Sales | F28: =UPPER(TRIM(G28)) -> SAL05 | G28: SAL05 | H28: =DATEVALUE(TEXT(J28, "dd-mmm-yyyy")) -> 43732 | I28: =DATEDIF(H28, TODAY(), "Y") -> 6 | J28: 09/24/2019 | K28: 77610 | L28: 88 | M28: Actv | N28: {=_xlfn.SWITCH(TRIM(PROPER(M28)), "Active", "Active", "Actv", "Active", "Left", "Left", "Resigned", "Left", "Unknown")} -> Active | O28: =_xlfn.XLOOKUP(L28, Lookup_Performance!$A$2:$A$6, Lookup_Performance!$C$2:$C$6, "No Score", -1) -> Exceeding | P28: =_xlfn.XLOOKUP(L28, Lookup_Performance!$A$2:$A$6, Lookup_Performance!$D$2:$D$6, 0, -1) -> 0.08 | Q28: =K28*P28 -> 6208.8
A29: EMP146 | B29: Thomas | C29: Rodriguez | D29: =IF(AND(ISBLANK(B29), ISBLANK(C29)), "- -", IF(ISBLANK(B29), "- " & TRIM(PROPER(C29)), IF(ISBLANK(C29), TRIM(PROPER(B29)) & " -", _xlfn.TEXTJOIN(" ", TRUE, TRIM(PROPER(B29)), TRIM(PROPER(C29)))))) -> Thomas Rodriguez | E29: =_xlfn.XLOOKUP(F29, Lookup_Departments!$A$2:$A$7, Lookup_Departments!$B$2:$B$7, "Unknown") -> Information Technology | F29: =UPPER(TRIM(G29)) -> IT02 | G29: it02 | H29: =DATEVALUE(TEXT(J29, "dd-mmm-yyyy")) -> 44765 | I29: =DATEDIF(H29, TODAY(), "Y") -> 3 | J29: 44765 | K29: 50873 | L29: 90 | M29: Active | N29: {=_xlfn.SWITCH(TRIM(PROPER(M29)), "Active", "Active", "Actv", "Active", "Left", "Left", "Resigned", "Left", "Unknown")} -> Active | O29: =_xlfn.XLOOKUP(L29, Lookup_Performance!$A$2:$A$6, Lookup_Performance!$C$2:$C$6, "No Score", -1) -> Exceeding | P29: =_xlfn.XLOOKUP(L29, Lookup_Performance!$A$2:$A$6, Lookup_Performance!$D$2:$D$6, 0, -1) -> 0.08 | Q29: =K29*P29 -> 4069.84
A30: EMP099 | B30: Michael | C30: Wilson | D30: =IF(AND(ISBLANK(B30), ISBLANK(C30)), "- -", IF(ISBLANK(B30), "- " & TRIM(PROPER(C30)), IF(ISBLANK(C30), TRIM(PROPER(B30)) & " -", _xlfn.TEXTJOIN(" ", TRUE, TRIM(PROPER(B30)), TRIM(PROPER(C30)))))) -> Michael Wilson | E30: =_xlfn.XLOOKUP(F30, Lookup_Departments!$A$2:$A$7, Lookup_Departments!$B$2:$B$7, "Unknown") -> Finance | F30: =UPPER(TRIM(G30)) -> FIN03 | G30: fin03 | H30: =DATEVALUE(TEXT(J30, "dd-mmm-yyyy")) -> 43233 | I30: =DATEDIF(H30, TODAY(), "Y") -> 8 | J30: 13-May-18 | K30: 85312 | L30: 66 | M30: active | N30: {=_xlfn.SWITCH(TRIM(PROPER(M30)), "Active", "Active", "Actv", "Active", "Left", "Left", "Resigned", "Left", "Unknown")} -> Active | O30: =_xlfn.XLOOKUP(L30, Lookup_Performance!$A$2:$A$6, Lookup_Performance!$C$2:$C$6, "No Score", -1) -> Developing | P30: =_xlfn.XLOOKUP(L30, Lookup_Performance!$A$2:$A$6, Lookup_Performance!$D$2:$D$6, 0, -1) -> 0.02 | Q30: =K30*P30 -> 1706.24
A31: EMP015 | B31: John | C31: Rodriguez | D31: =IF(AND(ISBLANK(B31), ISBLANK(C31)), "- -", IF(ISBLANK(B31), "- " & TRIM(PROPER(C31)), IF(ISBLANK(C31), TRIM(PROPER(B31)) & " -", _xlfn.TEXTJOIN(" ", TRUE, TRIM(PROPER(B31)), TRIM(PROPER(C31)))))) -> John Rodriguez | E31: =_xlfn.XLOOKUP(F31, Lookup_Departments!$A$2:$A$7, Lookup_Departments!$B$2:$B$7, "Unknown") -> Sales | F31: =UPPER(TRIM(G31)) -> SAL05 | G31: SAL05 | H31: =DATEVALUE(TEXT(J31, "dd-mmm-yyyy")) -> 42202 | I31: =DATEDIF(H31, TODAY(), "Y") -> 10 | J31: 42202 | K31: 83604 | L31: 68 | M31: active | N31: {=_xlfn.SWITCH(TRIM(PROPER(M31)), "Active", "Active", "Actv", "Active", "Left", "Left", "Resigned", "Left", "Unknown")} -> Active | O31: =_xlfn.XLOOKUP(L31, Lookup_Performance!$A$2:$A$6, Lookup_Performance!$C$2:$C$6, "No Score", -1) -> Developing | P31: =_xlfn.XLOOKUP(L31, Lookup_Performance!$A$2:$A$6, Lookup_Performance!$D$2:$D$6, 0, -1) -> 0.02 | Q31: =K31*P31 -> 1672.08
A32: EMP076 | B32: Thomas | C32: Hernandez | D32: =IF(AND(ISBLANK(B32), ISBLANK(C32)), "- -", IF(ISBLANK(B32), "- " & TRIM(PROPER(C32)), IF(ISBLANK(C32), TRIM(PROPER(B32)) & " -", _xlfn.TEXTJOIN(" ", TRUE, TRIM(PROPER(B32)), TRIM(PROPER(C32)))))) -> Thomas Hernandez | E32: =_xlfn.XLOOKUP(F32, Lookup_Departments!$A$2:$A$7, Lookup_Departments!$B$2:$B$7, "Unknown") -> Operations | F32: =UPPER(TRIM(G32)) -> OPS06 | G32: OPS06 | H32: =DATEVALUE(TEXT(J32, "dd-mmm-yyyy")) -> 42221 | I32: =DATEDIF(H32, TODAY(), "Y") -> 10 | J32: 05-Aug-15 | K32: 97055 | L32: 80 | M32: Actv | N32: {=_xlfn.SWITCH(TRIM(PROPER(M32)), "Active", "Active", "Actv", "Active", "Left", "Left", "Resigned", "Left", "Unknown")} -> Active | O32: =_xlfn.XLOOKUP(L32, Lookup_Performance!$A$2:$A$6, Lookup_Performance!$C$2:$C$6, "No Score", -1) -> Achieving | P32: =_xlfn.XLOOKUP(L32, Lookup_Performance!$A$2:$A$6, Lookup_Performance!$D$2:$D$6, 0, -1) -> 0.05 | Q32: =K32*P32 -> 4852.75
A33: EMP137 | B33: Michael | C33: Johnson | D33: =IF(AND(ISBLANK(B33), ISBLANK(C33)), "- -", IF(ISBLANK(B33), "- " & TRIM(PROPER(C33)), IF(ISBLANK(C33), TRIM(PROPER(B33)) & " -", _xlfn.TEXTJOIN(" ", TRUE, TRIM(PROPER(B33)), TRIM(PROPER(C33)))))) -> Michael Johnson | E33: =_xlfn.XLOOKUP(F33, Lookup_Departments!$A$2:$A$7, Lookup_Departments!$B$2:$B$7, "Unknown") -> Information Technology | F33: =UPPER(TRIM(G33)) -> IT02 | G33: IT02 | H33: =DATEVALUE(TEXT(J33, "dd-mmm-yyyy")) -> 45195 | I33: =DATEDIF(H33, TODAY(), "Y") -> 2 | J33: 45195 | K33: 66069 | L33: 72 | M33: Actv | N33: {=_xlfn.SWITCH(TRIM(PROPER(M33)), "Active", "Active", "Actv", "Active", "Left", "Left", "Resigned", "Left", "Unknown")} -> Active | O33: =_xlfn.XLOOKUP(L33, Lookup_Performance!$A$2:$A$6, Lookup_Performance!$C$2:$C$6, "No Score", -1) -> Achieving | P33: =_xlfn.XLOOKUP(L33, Lookup_Performance!$A$2:$A$6, Lookup_Performance!$D$2:$D$6, 0, -1) -> 0.05 | Q33: =K33*P33 -> 3303.45
A34: EMP056 | B34: Sarah | C34: Brown | D34: =IF(AND(ISBLANK(B34), ISBLANK(C34)), "- -", IF(ISBLANK(B34), "- " & TRIM(PROPER(C34)), IF(ISBLANK(C34), TRIM(PROPER(B34)) & " -", _xlfn.TEXTJOIN(" ", TRUE, TRIM(PROPER(B34)), TRIM(PROPER(C34)))))) -> Sarah Brown | E34: =_xlfn.XLOOKUP(F34, Lookup_Departments!$A$2:$A$7, Lookup_Departments!$B$2:$B$7, "Unknown") -> Information Technology | F34: =UPPER(TRIM(G34)) -> IT02 | G34: it02 | H34: =DATEVALUE(TEXT(J34, "dd-mmm-yyyy")) -> 43626 | I34: =DATEDIF(H34, TODAY(), "Y") -> 7 | J34: 10-Jun-19 | K34: 90157 | L34: 58 | M34: active | N34: {=_xlfn.SWITCH(TRIM(PROPER(M34)), "Active", "Active", "Actv", "Active", "Left", "Left", "Resigned", "Left", "Unknown")} -> Active | O34: =_xlfn.XLOOKUP(L34, Lookup_Performance!$A$2:$A$6, Lookup_Performance!$C$2:$C$6, "No Score", -1) -> Developing | P34: =_xlfn.XLOOKUP(L34, Lookup_Performance!$A$2:$A$6, Lookup_Performance!$D$2:$D$6, 0, -1) -> 0.02 | Q34: =K34*P34 -> 1803.14
A35: EMP125 | B35: Jane | C35: Martinez | D35: =IF(AND(ISBLANK(B35), ISBLANK(C35)), "- -", IF(ISBLANK(B35), "- " & TRIM(PROPER(C35)), IF(ISBLANK(C35), TRIM(PROPER(B35)) & " -", _xlfn.TEXTJOIN(" ", TRUE, TRIM(PROPER(B35)), TRIM(PROPER(C35)))))) -> Jane Martinez | E35: =_xlfn.XLOOKUP(F35, Lookup_Departments!$A$2:$A$7, Lookup_Departments!$B$2:$B$7, "Unknown") -> Human Resources | F35: =UPPER(TRIM(G35)) -> HR01 | G35: HR01 | H35: =DATEVALUE(TEXT(J35, "dd-mmm-yyyy")) -> 44578 | I35: =DATEDIF(H35, TODAY(), "Y") -> 4 | J35: 44578 | K35: 59899 | L35: 78 | M35: Actv | N35: {=_xlfn.SWITCH(TRIM(PROPER(M35)), "Active", "Active", "Actv", "Active", "Left", "Left", "Resigned", "Left", "Unknown")} -> Active | O35: =_xlfn.XLOOKUP(L35, Lookup_Performance!$A$2:$A$6, Lookup_Performance!$C$2:$C$6, "No Score", -1) -> Achieving | P35: =_xlfn.XLOOKUP(L35, Lookup_Performance!$A$2:$A$6, Lookup_Performance!$D$2:$D$6, 0, -1) -> 0.05 | Q35: =K35*P35 -> 2994.95
A36: EMP085 | B36: Emily | C36: Jones | D36: =IF(AND(ISBLANK(B36), ISBLANK(C36)), "- -", IF(ISBLANK(B36), "- " & TRIM(PROPER(C36)), IF(ISBLANK(C36), TRIM(PROPER(B36)) & " -", _xlfn.TEXTJOIN(" ", TRUE, TRIM(PROPER(B36)), TRIM(PROPER(C36)))))) -> Emily Jones | E36: =_xlfn.XLOOKUP(F36, Lookup_Departments!$A$2:$A$7, Lookup_Departments!$B$2:$B$7, "Unknown") -> Finance | F36: =UPPER(TRIM(G36)) -> FIN03 | G36: FIN03 | H36: =DATEVALUE(TEXT(J36, "dd-mmm-yyyy")) -> 42919 | I36: =DATEDIF(H36, TODAY(), "Y") -> 9 | J36: 03-Jul-17 | K36: 113389 | L36: 30 | M36: ACTIVE | N36: {=_xlfn.SWITCH(TRIM(PROPER(M36)), "Active", "Active", "Actv", "Active", "Left", "Left", "Resigned", "Left", "Unknown")} -> Active | O36: =_xlfn.XLOOKUP(L36, Lookup_Performance!$A$2:$A$6, Lookup_Performance!$C$2:$C$6, "No Score", -1) -> Needs Improvement | P36: =_xlfn.XLOOKUP(L36, Lookup_Performance!$A$2:$A$6, Lookup_Performance!$D$2:$D$6, 0, -1) -> 0 | Q36: =K36*P36 -> 0
A37: EMP106 | C37: Brown | D37: =IF(AND(ISBLANK(B37), ISBLANK(C37)), "- -", IF(ISBLANK(B37), "- " & TRIM(PROPER(C37)), IF(ISBLANK(C37), TRIM(PROPER(B37)) & " -", _xlfn.TEXTJOIN(" ", TRUE, TRIM(PROPER(B37)), TRIM(PROPER(C37)))))) -> - Brown | E37: =_xlfn.XLOOKUP(F37, Lookup_Departments!$A$2:$A$7, Lookup_Departments!$B$2:$B$7, "Unknown") -> Information Technology | F37: =UPPER(TRIM(G37)) -> IT02 | G37: IT02 | H37: =DATEVALUE(TEXT(J37, "dd-mmm-yyyy")) -> 42248 | I37: =DATEDIF(H37, TODAY(), "Y") -> 10 | J37: 01-Sep-15 | K37: 102691 | L37: 52 | M37: Active | N37: {=_xlfn.SWITCH(TRIM(PROPER(M37)), "Active", "Active", "Actv", "Active", "Left", "Left", "Resigned", "Left", "Unknown")} -> Active | O37: =_xlfn.XLOOKUP(L37, Lookup_Performance!$A$2:$A$6, Lookup_Performance!$C$2:$C$6, "No Score", -1) -> Developing | P37: =_xlfn.XLOOKUP(L37, Lookup_Performance!$A$2:$A$6, Lookup_Performance!$D$2:$D$6, 0, -1) -> 0.02 | Q37: =K37*P37 -> 2053.82
A38: EMP043 | B38: John | C38: Wilson | D38: =IF(AND(ISBLANK(B38), ISBLANK(C38)), "- -", IF(ISBLANK(B38), "- " & TRIM(PROPER(C38)), IF(ISBLANK(C38), TRIM(PROPER(B38)) & " -", _xlfn.TEXTJOIN(" ", TRUE, TRIM(PROPER(B38)), TRIM(PROPER(C38)))))) -> John Wilson | E38: =_xlfn.XLOOKUP(F38, Lookup_Departments!$A$2:$A$7, Lookup_Departments!$B$2:$B$7, "Unknown") -> Operations | F38: =UPPER(TRIM(G38)) -> OPS06 | G38: OPS06 | H38: =DATEVALUE(TEXT(J38, "dd-mmm-yyyy")) -> 44776 | I38: =DATEDIF(H38, TODAY(), "Y") -> 3 | J38: 03-Aug-22 | K38: 111845 | L38: 98 | M38: active | N38: {=_xlfn.SWITCH(TRIM(PROPER(M38)), "Active", "Active", "Actv", "Active", "Left", "Left", "Resigned", "Left", "Unknown")} -> Active | O38: =_xlfn.XLOOKUP(L38, Lookup_Performance!$A$2:$A$6, Lookup_Performance!$C$2:$C$6, "No Score", -1) -> Outstanding | P38: =_xlfn.XLOOKUP(L38, Lookup_Performance!$A$2:$A$6, Lookup_Performance!$D$2:$D$6, 0, -1) -> 0.12 | Q38: =K38*P38 -> 13421.4
A39: EMP068 | B39: Melissa | C39: Brown | D39: =IF(AND(ISBLANK(B39), ISBLANK(C39)), "- -", IF(ISBLANK(B39), "- " & TRIM(PROPER(C39)), IF(ISBLANK(C39), TRIM(PROPER(B39)) & " -", _xlfn.TEXTJOIN(" ", TRUE, TRIM(PROPER(B39)), TRIM(PROPER(C39)))))) -> Melissa Brown | E39: =_xlfn.XLOOKUP(F39, Lookup_Departments!$A$2:$A$7, Lookup_Departments!$B$2:$B$7, "Unknown") -> Sales | F39: =UPPER(TRIM(G39)) -> SAL05 | G39: SAL05 | H39: =DATEVALUE(TEXT(J39, "dd-mmm-yyyy")) -> 44741 | I39: =DATEDIF(H39, TODAY(), "Y") -> 4 | J39: 06/29/2022 | K39: 69219 | L39: 93 | M39: Actv | N39: {=_xlfn.SWITCH(TRIM(PROPER(M39)), "Active", "Active", "Actv", "Active", "Left", "Left", "Resigned", "Left", "Unknown")} -> Active | O39: =_xlfn.XLOOKUP(L39, Lookup_Performance!$A$2:$A$6, Lookup_Performance!$C$2:$C$6, "No Score", -1) -> Exceeding | P39: =_xlfn.XLOOKUP(L39, Lookup_Performance!$A$2:$A$6, Lookup_Performance!$D$2:$D$6, 0, -1) -> 0.08 | Q39: =K39*P39 -> 5537.52
A40: EMP128 | B40: Michael | C40: Smith | D40: =IF(AND(ISBLANK(B40), ISBLANK(C40)), "- -", IF(ISBLANK(B40), "- " & TRIM(PROPER(C40)), IF(ISBLANK(C40), TRIM(PROPER(B40)) & " -", _xlfn.TEXTJOIN(" ", TRUE, TRIM(PROPER(B40)), TRIM(PROPER(C40)))))) -> Michael Smith | E40: =_xlfn.XLOOKUP(F40, Lookup_Departments!$A$2:$A$7, Lookup_Departments!$B$2:$B$7, "Unknown") -> Finance | F40: =UPPER(TRIM(G40)) -> FIN03 | G40: FIN03 | H40: =DATEVALUE(TEXT(J40, "dd-mmm-yyyy")) -> 43949 | I40: =DATEDIF(H40, TODAY(), "Y") -> 6 | J40: 43949 | K40: 83604 | L40: 80 | M40: left | N40: {=_xlfn.SWITCH(TRIM(PROPER(M40)), "Active", "Active", "Actv", "Active", "Left", "Left", "Resigned", "Left", "Unknown")} -> Left | O40: =_xlfn.XLOOKUP(L40, Lookup_Performance!$A$2:$A$6, Lookup_Performance!$C$2:$C$6, "No Score", -1) -> Achieving | P40: =_xlfn.XLOOKUP(L40, Lookup_Performance!$A$2:$A$6, Lookup_Performance!$D$2:$D$6, 0, -1) -> 0.05 | Q40: =K40*P40 -> 4180.2
...

Sheet Analysis
A2: Total Employee | D2: Total Salary | G2: Attrition Rate by Department
A3: Row Labels | B3: Count of Emp ID | D3: Row Labels | E3: Sum of Salary | G3: Count of Emp ID | H3: Column Labels
A4: Information Technology | B4: 36 | D4: Finance | E4: 1481951 | G4: Row Labels | H4: Active | I4: Left | J4: Grand Total
A5: Sales | B5: 31 | D5: Human Resources | E5: 1539653 | G5: Finance | H5: 0.82352941 | I5: 0.17647059 | J5: 1
A6: Operations | B6: 29 | D6: Marketing | E6: 1622751 | G6: Human Resources | H6: 0.83333333 | I6: 0.16666667 | J6: 1
A7: Marketing | B7: 19 | D7: Operations | E7: 2321448 | G7: Information Technology | H7: 0.77777778 | I7: 0.22222222 | J7: 1
A8: Human Resources | B8: 18 | D8: Sales | E8: 2676326 | G8: Marketing | H8: 0.84210526 | I8: 0.15789474 | J8: 1
A9: Finance | B9: 17 | D9: Information Technology | E9: 2898462 | G9: Operations | H9: 0.62068966 | I9: 0.37931034 | J9: 1
A10: Grand Total | B10: 150 | D10: Grand Total | E10: 12540591 | G10: Sales | H10: 0.80645161 | I10: 0.19354839 | J10: 1
B11: 150 | G11: Grand Total | H11: 0.77333333 | I11: 0.22666667 | J11: 1
A13: Performance By Status | D13: Bonus Payout | G13: Attrition by Performance Band
A14: Row Labels | B14: Average of Performance Score | D14: Row Labels | E14: Sum of Eligible Bonus Amount | G14: Count of Emp ID | H14: Column Labels
A15: Active | B15: 67.862069 | D15: Achieving | E15: 197912.8 | G15: Row Labels | H15: Active | I15: Left | J15: Grand Total
A16: Left | B16: 69.264706 | D16: Exceeding | E16: 144689.44 | G16: Achieving | H16: 0.69387755 | I16: 0.30612245 | J16: 1
A17: Grand Total | B17: 68.18 | D17: Outstanding | E17: 92411.52 | G17: Developing | H17: 0.80487805 | I17: 0.19512195 | J17: 1
D18: Developing | E18: 71514.94 | G18: Exceeding | H18: 0.72727273 | I18: 0.27272727 | J18: 1
A19: Average Salary by Performance Band | D19: Needs Improvement | E19: 0 | G19: Needs Improvement | H19: 0.82142857 | I19: 0.17857143 | J19: 1
A20: Row Labels | B20: Average of Salary | D20: Grand Total | E20: 506528.7 | G20: Outstanding | H20: 1 | I20: 0 | J20: 1
A21: Outstanding | B21: 77009.6 | G21: Grand Total | H21: 0.77333333 | I21: 0.22666667 | J21: 1
A22: Achieving | B22: 80780.735 | D22: Employee by Service Year
A23: Exceeding | B23: 82209.909 | D23: Row Labels | E23: Count of Emp ID | I23: 0.22666667
A24: Needs Improvement | B24: 86709.786 | D24: 11 | E24: 4
A25: Developing | B25: 87213.341 | D25: 2 | E25: 9 | G25: Employee by Service Year
A26: Grand Total | B26: 83603.94 | D26: 5 | E26: 12 | G26: Average of Year of Service
B27: 83603.94 | D27: 10 | E27: 14 | G27: 6.42
D28: 6 | E28: 16 | G28: 6.42
D29: 3 | E29: 16
D30: 7 | E30: 17
D31: 8 | E31: 20
D32: 4 | E32: 20
D33: 9 | E33: 22
D34: Grand Total | E34: 150

Sheet Charts

Sheet Executive Dashboard
